<?xml version="1.0"?>
<robot xmlns:xacro="http://www.ros.org/wiki/xacro"  name="robot">

    <xacro:include filename="inertial_macros.xacro"/>

    <xacro:macro name="wheel" params="name x y wheel_mass wheel_radius wheel_thickness">

        <link name="wheel_${name}_link">

            <visual name="">
                <origin xyz="0.0 0.0 0.0" rpy="0.0 0.0 0.0"/>
                <geometry>
                    <cylinder radius="${wheel_radius}" length="${wheel_thickness}"/>
                </geometry>
                <material name="almostblack" >
                    <color rgba="0.027450980392156862 0.050980392156862744 0.050980392156862744 1.0" />
                </material>
            </visual>

            <collision>
                    <origin xyz="0.0 0.0 0.0" rpy="0.0 0.0 0.0"/>
                    <geometry>
                        <sphere radius="${wheel_radius}"/>
                        <!-- <cylinder radius="${wheel_radius}" length="${wheel_thickness}"/> -->
                    </geometry>
            </collision>

            <xacro:inertial_cylinder mass="${wheel_mass}" length="${wheel_thickness}" radius="${wheel_radius}">
                <origin xyz="0 0 0" rpy="0 0 0"/>
            </xacro:inertial_cylinder>
        </link>

        <gazebo reference = "wheel_${name}_link">
            <material>Gazebo/Black</material> 
        </gazebo>

        <joint name="wheel_${name}_joint" type="continuous">
            <parent link="chassis"/>
            <child link="wheel_${name}_link"/>
            <origin xyz="${x} ${y} -0.015" rpy="-1.57 0.0 0.0"/>
            <axis xyz=".0 .0 1.0"/>
        </joint>

    </xacro:macro>

</robot>